INFO: Starting training:
        Epochs:          5
        Batch size:      1
        Learning rate:   1e-05
        Training size:   48
        Validation size: 5
        Checkpoints:     True
        Device:          cpu
        Images scaling:  0.5
        Mixed Precision: False


Epoch 1/5:   8%|█████████▏                                                                                                    | 4/48 [00:07<01:24,  1.91s/img, loss (batch)=0.732]
Traceback (most recent call last):
  File "train.py", line 183, in <module>
    train_net(net=net,
  File "train.py", line 122, in train_net
    val_score = evaluate(net, val_loader, device)
  File "/home/inge/Pytorch-UNet/evaluate.py", line 14, in evaluate
    for batch in tqdm(dataloader, total=num_val_batches, desc='Validation round', unit='batch', leave=False):
  File "/home/inge/anaconda3/envs/unet/lib/python3.8/site-packages/tqdm/std.py", line 1185, in __iter__
    for obj in iterable:
  File "/home/inge/anaconda3/envs/unet/lib/python3.8/site-packages/torch/utils/data/dataloader.py", line 521, in __next__
    data = self._next_data()
  File "/home/inge/anaconda3/envs/unet/lib/python3.8/site-packages/torch/utils/data/dataloader.py", line 1203, in _next_data
    return self._process_data(data)
  File "/home/inge/anaconda3/envs/unet/lib/python3.8/site-packages/torch/utils/data/dataloader.py", line 1229, in _process_data
    data.reraise()
  File "/home/inge/anaconda3/envs/unet/lib/python3.8/site-packages/torch/_utils.py", line 425, in reraise
    raise self.exc_type(msg)
AssertionError: Caught AssertionError in DataLoader worker process 0.
Original Traceback (most recent call last):
  File "/home/inge/anaconda3/envs/unet/lib/python3.8/site-packages/torch/utils/data/_utils/worker.py", line 287, in _worker_loop
    data = fetcher.fetch(index)
  File "/home/inge/anaconda3/envs/unet/lib/python3.8/site-packages/torch/utils/data/_utils/fetch.py", line 44, in fetch
    data = [self.dataset[idx] for idx in possibly_batched_index]
  File "/home/inge/anaconda3/envs/unet/lib/python3.8/site-packages/torch/utils/data/_utils/fetch.py", line 44, in <listcomp>
    data = [self.dataset[idx] for idx in possibly_batched_index]
  File "/home/inge/anaconda3/envs/unet/lib/python3.8/site-packages/torch/utils/data/dataset.py", line 311, in __getitem__
    return self.dataset[self.indices[idx]]
  File "/home/inge/Pytorch-UNet/utils/data_loading.py", line 66, in __getitem__
    assert img.size == mask.size, \
AssertionError: Image and mask {name} should be the same size, but are {img.size} and {mask.size}